Workbook

Sheet nga_admpop_adm0_2020
A1: ADM0_NAME | B1: ADM0_PCODE | C1: F_TL | D1: M_TL | E1: T_TL | F1: F_00_04 | G1: F_05_09 | H1: F_10_14 | I1: F_15_19 | J1: F_20_24 | K1: F_25_29 | L1: F_30_34 | M1: F_35_39 | N1: F_40_44 | O1: F_45_49 | P1: F_50_54 | Q1: F_55_59 | R1: F_60_64 | S1: F_65_69 | T1: F_70_74 | U1: F_75_79 | V1: F_80Plus | W1: M_00_04 | X1: M_05_09 | Y1: M_10_14 | Z1: M_15_19 | AA1: M_20_24 | AB1: M_25_29 | AC1: M_30_34 | AD1: M_35_39 | AE1: M_40_44 | AF1: M_45_49 | AG1: M_50_54 | AH1: M_55_59 | AI1: M_60_64 | AJ1: M_65_69 | AK1: M_70_74 | AL1: M_75_79 | AM1: M_80Plus | AN1: T_00_04 | AO1: T_05_09 | AP1: T_10_14 | AQ1: T_15_19 | AR1: T_20_24 | AS1: T_25_29 | AT1: T_30_34 | AU1: T_35_39 | AV1: T_40_44 | AW1: T_45_49 | AX1: T_50_54 | AY1: T_55_59 | AZ1: T_60_64 | BA1: T_65_69 | BB1: T_70_74 | BC1: T_75_79 | BD1: T_80Plus
A2: NIGERIA | B2: NG | C2: 100473260 | D2: 104435960 | E2: 204909220 | F2: 15713253 | G2: 13740497 | H2: 12305947 | I2: 10974474 | J2: 9109497 | K2: 7696113 | L2: 6543803 | M2: 5577463 | N2: 4629290 | O2: 3617274 | P2: 2903755 | Q2: 2363122 | R2: 1848775 | S2: 1415387 | T2: 1008663 | U2: 609086 | V2: 416861 | W2: 16494093 | X2: 14394113 | Y2: 12886243 | Z2: 11481793 | AA2: 9479149 | AB2: 7999304 | AC2: 6847228 | AD2: 5885417 | AE2: 4915691 | AF2: 3897001 | AG2: 3038057 | AH2: 2334506 | AI2: 1737882 | AJ2: 1276610 | AK2: 899216 | AL2: 533838 | AM2: 335819 | AN2: 32207346 | AO2: 28134610 | AP2: 25192190 | AQ2: 22456267 | AR2: 18588646 | AS2: 15695417 | AT2: 13391031 | AU2: 11462880 | AV2: 9544981 | AW2: 7514275 | AX2: 5941812 | AY2: 4697628 | AZ2: 3586657 | BA2: 2691997 | BB2: 1907879 | BC2: 1142924 | BD2: 752680

Sheet Age groupings population
A1: STATES | B1: LOCAL GOVERNMENTS | C1: SenDist_en | D1: FEMALE_TL | E1: MALE_TL | F1: FEMALES 00_04 | G1: FEMALES_05_09 | H1: FEMALES_10_14 | I1: FEMALES_15_19 | J1: FEMALES_20_24 | K1: FEMALES_25_29 | L1: FEMALES_30_34 | M1: FEMALES_35_39 | N1: FEMALES_40_44 | O1: FEMALES_45_49 | P1: FEMALES_50_54 | Q1: FEMALES_55_59 | R1: FEMALES_60_64 | S1: FEMALES_65_69 | T1: FEMALES_70_74 | U1: FEMALES_75_79 | V1: FEMALES_80Plus | W1: MALES_00_04 | X1: MALES_05_09 | Y1: MALES_10_14 | Z1: MALES_15_19 | AA1: MALES_20_24 | AB1: MALES_25_29 | AC1: MALES_30_34 | AD1: MALES_35_39 | AE1: MALES_40_44 | AF1: MALES_45_49 | AG1: MALES_50_54 | AH1: MALES_55_59 | AI1: MALES_60_64 | AJ1: MALES_65_69 | AK1: MALES_70_74 | AL1: MALES 75_79 | AM1: MALES 80+ | AN1: LGA TOTALS
A2: LAGOS | B2: ALIMOSHO | C2: Lagos West | D2: 1713518 | E2: 1786291 | F2: 244714 | G2: 199526 | H2: 192694 | I2: 168179 | J2: 166374 | K2: 163619 | L2: 143016 | M2: 123750 | N2: 87222 | O2: 71082 | P2: 45092 | Q2: 44444 | R2: 21474 | S2: 19540 | T2: 9955 | U2: 7683 | V2: 5154 | W2: 242599 | X2: 196590 | Y2: 175867 | Z2: 166058 | AA2: 186837 | AB2: 181380 | AC2: 160248 | AD2: 148728 | AE2: 99964 | AF2: 81320 | AG2: 46701 | AH2: 49143 | AI2: 20451 | AJ2: 18227 | AK2: 5992 | AL2: 3978 | AM2: 2208 | AN2: =SUM(F2:AM2) -> 3499809
A3: FEDERAL CAPITAL TERRITORY | B3: ABUJA MUNICIPAL | C3: Federal Capital Territory | D3: 1347926 | E3: 1621481 | F3: 210332 | G3: 166258 | H3: 156402 | I3: 132046 | J3: 152654 | K3: 153027 | L3: 117544 | M3: 90746 | N3: 57563 | O3: 41789 | P3: 22792 | Q3: 19323 | R3: 9214 | S3: 8298 | T3: 4626 | U3: 3203 | V3: 2109 | W3: 210578 | X3: 157768 | Y3: 128930 | Z3: 115425 | AA3: 166438 | AB3: 220682 | AC3: 184390 | AD3: 153862 | AE3: 97593 | AF3: 81493 | AG3: 40885 | AH3: 35840 | AI3: 11432 | AJ3: 9051 | AK3: 3215 | AL3: 2392 | AM3: 1507 | AN3: =SUM(F3:AM3) -> 2969407
A4: LAGOS | B4: AJEROMI-IFELODUN | C4: Lagos West | D4: 690331 | E4: 741424 | F4: 86985 | G4: 75709 | H4: 80676 | I4: 78762 | J4: 77442 | K4: 64364 | L4: 50366 | M4: 43729 | N4: 34621 | O4: 30277 | P4: 20656 | Q4: 18541 | R4: 10698 | S4: 8267 | T4: 4333 | U4: 2932 | V4: 1973 | W4: 90218 | X4: 75292 | Y4: 74126 | Z4: 77147 | AA4: 87966 | AB4: 80268 | AC4: 63495 | AD4: 52011 | AE4: 35451 | AF4: 34140 | AG4: 22258 | AH4: 22506 | AI4: 10187 | AJ4: 9006 | AK4: 3783 | AL4: 2435 | AM4: 1135 | AN4: =SUM(F4:AM4) -> 1431755
A5: LAGOS | B5: IKORODU | C5: Lagos East | D5: 637191 | E5: 673852 | F5: 94697 | G5: 76276 | H5: 71691 | I5: 61607 | J5: 60816 | K5: 58669 | L5: 52911 | M5: 46054 | N5: 31962 | O5: 24319 | P5: 15069 | Q5: 14612 | R5: 9136 | S5: 8780 | T5: 4885 | U5: 3485 | V5: 2222 | W5: 95755 | X5: 74575 | Y5: 66500 | Z5: 62369 | AA5: 71610 | AB5: 68579 | AC5: 59822 | AD5: 56368 | AE5: 37814 | AF5: 29840 | AG5: 16558 | AH5: 15488 | AI5: 6744 | AJ5: 6569 | AK5: 2416 | AL5: 1934 | AM5: 911 | AN5: =SUM(F5:AM5) -> 1311043
A6: OGUN | B6: IFO | C6: Ogun Central | D6: 642834 | E6: 651792 | F6: 95462 | G6: 79643 | H6: 74439 | I6: 60652 | J6: 58429 | K6: 56310 | L6: 49695 | M6: 45967 | N6: 33120 | O6: 26275 | P6: 17046 | Q6: 16176 | R6: 9067 | S6: 8907 | T6: 5262 | U6: 4010 | V6: 2374 | W6: 95428 | X6: 78393 | Y6: 68470 | Z6: 60821 | AA6: 62101 | AB6: 58819 | AC6: 53125 | AD6: 50886 | AE6: 36169 | AF6: 30941 | AG6: 18347 | AH6: 18192 | AI6: 8041 | AJ6: 6695 | AK6: 2694 | AL6: 1795 | AM6: 875 | AN6: =SUM(F6:AM6) -> 1294626
A7: LAGOS | B7: SURULERE | C7: Lagos Central | D7: 500187 | E7: 547580 | F7: 55710 | G7: 47701 | H7: 53650 | I7: 54646 | J7: 54701 | K7: 50433 | L7: 40950 | M7: 35548 | N7: 25667 | O7: 21772 | P7: 14487 | Q7: 15912 | R7: 9056 | S7: 9215 | T7: 4991 | U7: 3848 | V7: 1900 | W7: 56984 | X7: 46766 | Y7: 45399 | Z7: 51136 | AA7: 69834 | AB7: 69047 | AC7: 56835 | AD7: 46226 | AE7: 30689 | AF7: 25145 | AG7: 14661 | AH7: 14517 | AI7: 6670 | AJ7: 7019 | AK7: 3161 | AL7: 2513 | AM7: 978 | AN7: =SUM(F7:AM7) -> 1047767
A8: KANO | B8: NASSARAWA | C8: Kano Central | D8: 467494 | E8: 565158 | F8: 90480 | G8: 72114 | H8: 62452 | I8: 48217 | J8: 41026 | K8: 35580 | L8: 28051 | M8: 22510 | N8: 19499 | O8: 12169 | P8: 10890 | Q8: 7367 | R8: 5979 | S8: 3695 | T8: 3676 | U8: 1790 | V8: 1999 | W8: 96121 | X8: 77751 | Y8: 76169 | Z8: 65530 | AA8: 50627 | AB8: 43578 | AC8: 35889 | AD8: 30486 | AE8: 24169 | AF8: 18639 | AG8: 14078 | AH8: 12616 | AI8: 7114 | AJ8: 5568 | AK8: 3403 | AL8: 2078 | AM8: 1342 | AN8: =SUM(F8:AM8) -> 1032652
A9: OGUN | B9: ADO-ODO/OTA | C9: Ogun West | D9: 517361 | E9: 513468 | F9: 74785 | G9: 65163 | H9: 61859 | I9: 48116 | J9: 44600 | K9: 42136 | L9: 37354 | M9: 36448 | N9: 27140 | O9: 21657 | P9: 14851 | Q9: 13680 | R9: 9052 | S9: 9103 | T9: 5102 | U9: 3895 | V9: 2420 | W9: 73934 | X9: 64167 | Y9: 59120 | Z9: 49264 | AA9: 47045 | AB9: 43406 | AC9: 38224 | AD9: 37816 | AE9: 28755 | AF9: 24593 | AG9: 14968 | AH9: 13311 | AI9: 6847 | AJ9: 6265 | AK9: 2845 | AL9: 1922 | AM9: 986 | AN9: =SUM(F9:AM9) -> 1030829
A10: FEDERAL CAPITAL TERRITORY | B10: BWARI | C10: Federal Capital Territory | D10: 430569 | E10: 450374 | F10: 72312 | G10: 56958 | H10: 56108 | I10: 43224 | J10: 42073 | K10: 45752 | L10: 36036 | M10: 27221 | N10: 16202 | O10: 10866 | P10: 6656 | Q10: 5670 | R10: 3488 | S10: 3137 | T10: 2352 | U10: 1419 | V10: 1095 | W10: 72287 | X10: 53233 | Y10: 42984 | Z10: 34763 | AA10: 39225 | AB10: 48133 | AC10: 43947 | AD10: 40944 | AE10: 27341 | AF10: 21150 | AG10: 9786 | AH10: 7830 | AI10: 3073 | AJ10: 2728 | AK10: 1275 | AL10: 866 | AM10: 809 | AN10: =SUM(F10:AM10) -> 880943
A11: LAGOS | B11: KOSOFE | C11: Lagos East | D11: 392382 | E11: 445978 | F11: 48979 | G11: 40352 | H11: 41234 | I11: 40821 | J11: 42699 | K11: 40266 | L11: 34043 | M11: 28705 | N11: 20309 | O11: 16436 | P11: 10834 | Q11: 11326 | R11: 5699 | S11: 5225 | T11: 2580 | U11: 1841 | V11: 1033 | W11: 50662 | X11: 39193 | Y11: 36143 | Z11: 39280 | AA11: 55267 | AB11: 56924 | AC11: 48080 | AD11: 40319 | AE11: 26389 | AF11: 19497 | AG11: 11167 | AH11: 10433 | AI11: 4665 | AJ11: 4438 | AK11: 1762 | AL11: 1222 | AM11: 537 | AN11: =SUM(F11:AM11) -> 838360
A12: BAYELSA | B12: Yenegoa | C12: Bayelsa Central | D12: 374195 | E12: 402784 | F12: 44987 | G12: 47010 | H12: 46393 | I12: 44302 | J12: 35428 | K12: 30667 | L12: 26523 | M12: 24529 | N12: 18505 | O12: 15895 | P12: 10889 | Q12: 10118 | R12: 6904 | S12: 5863 | T12: 2816 | U12: 2172 | V12: 1194 | W12: 47508 | X12: 50578 | Y12: 49029 | Z12: 48549 | AA12: 41186 | AB12: 33551 | AC12: 28178 | AD12: 24425 | AE12: 20819 | AF12: 17110 | AG12: 12957 | AH12: 9740 | AI12: 7496 | AJ12: 5003 | AK12: 3415 | AL12: 2031 | AM12: 1209 | AN12: =SUM(F12:AM12) -> 776979
A13: LAGOS | B13: OSHODI-ISOLO | C13: Lagos West | D13: 365559 | E13: 401347 | F13: 45952 | G13: 37747 | H13: 40344 | I13: 39082 | J13: 40647 | K13: 37768 | L13: 29875 | M13: 25218 | N13: 17577 | O13: 15332 | P13: 10168 | Q13: 10342 | R13: 5277 | S13: 4858 | T13: 2455 | U13: 1845 | V13: 1072 | W13: 45757 | X13: 36349 | Y13: 34367 | Z13: 37218 | AA13: 49730 | AB13: 48896 | AC13: 40752 | AD13: 34567 | AE13: 22298 | AF13: 18122 | AG13: 10496 | AH13: 10619 | AI13: 4444 | AJ13: 4349 | AK13: 1681 | AL13: 1127 | AM13: 575 | AN13: =SUM(F13:AM13) -> 766906
... A774: KOGI | B774: OGORI/MAGONGO | C774: Kogi Central | D774: 17881 | E774: 18153 | F774: 3159 | G774: 2508 | H774: 2181 | I774: 1916 | J774: 1570 | K774: 1337 | L774: 1126 | M774: 943 | N774: 776 | O774: 554 | P774: 422 | Q774: 480 | R774: 340 | S774: 295 | T774: 106 | U774: 122 | V774: 46 | W774: 3302 | X774: 2657 | Y774: 2231 | Z774: 2025 | AA774: 1560 | AB774: 1326 | AC774: 1090 | AD774: 966 | AE774: 811 | AF774: 576 | AG774: 478 | AH774: 351 | AI774: 274 | AJ774: 233 | AK774: 126 | AL774: 90 | AM774: 57 | AN774: =SUM(F774:AM774) -> 36034

Sheet nga_admpop_SenDist_2020
A1: STATES | B1: Local Govt | C1: SenDist_en | D1: Female_TotaL | E1: Male_TotaL | F1: LGA Totals | G1: F_00_04 | H1: F_05_09 | I1: F_10_14 | J1: F_15_19 | K1: F_20_24 | L1: F_25_29 | M1: F_30_34 | N1: F_35_39 | O1: F_40_44 | P1: F_45_49 | Q1: F_50_54 | R1: F_55_59 | S1: F_60_64 | T1: F_65_69 | U1: F_70_74 | V1: F_75_79 | W1: F_80Plus | X1: M_00_04 | Y1: M_05_09 | Z1: M_10_14 | AA1: M_15_19 | AB1: M_20_24 | AC1: M_25_29 | AD1: M_30_34 | AE1: M_35_39 | AF1: M_40_44 | AG1: M_45_49 | AH1: M_50_54 | AI1: M_55_59 | AJ1: M_60_64 | AK1: M_65_69 | AL1: M_70_74 | AM1: M_75_79 | AN1: M_80Plus | AO1: T_00_04 | AP1: T_05_09 | AQ1: T_10_14 | AR1: T_15_19 | AS1: T_20_24 | AT1: T_25_29 | AU1: T_30_34 | AV1: T_35_39 | AW1: T_40_44 | AX1: T_45_49 | AY1: T_50_54 | AZ1: T_55_59 | BA1: T_60_64 | BB1: T_65_69 | BC1: T_70_74 | BD1: T_75_79 | BE1: T_80Plus
A2: LAGOS | B2: AGEGE | C2: Lagos West | D2: 4334372 | E2: 4653938 | F2: 8988310 | G2: 579722 | H2: 482096 | I2: 485423 | J2: 447045 | K2: 452695 | L2: 419923 | M2: 347996 | N2: 301064 | O2: 216546 | P2: 182350 | Q2: 120773 | R2: 118972 | S2: 62026 | T2: 55053 | U2: 28515 | V2: 21190 | W2: 12983 | X2: 581891 | Y2: 472032 | Z2: 435394 | AA2: 437684 | AB2: 534853 | AC2: 517162 | AD2: 432653 | AE2: 378920 | AF2: 252462 | AG2: 211467 | AH2: 124789 | AI2: 129784 | AJ2: 55708 | AK2: 51420 | AL2: 18849 | AM2: 12740 | AN2: 6130 | AO2: 1161613 | AP2: 954128 | AQ2: 920817 | AR2: 884729 | AS2: 987548 | AT2: 937085 | AU2: 780649 | AV2: 679984 | AW2: 469008 | AX2: 393817 | AY2: 245562 | AZ2: 248756 | BA2: 117734 | BB2: 106473 | BC2: 47364 | BD2: 33930 | BE2: 19113
A3: KANO | B3: DALA | C3: Kano Central | D3: 2725818 | E3: 3346731 | F3: 6072549 | G3: 531571 | H3: 418644 | I3: 340619 | J3: 291800 | K3: 242566 | L3: 202141 | M3: 164638 | N3: 126887 | O3: 113418 | P3: 70452 | Q3: 67622 | R3: 42445 | S3: 39734 | T3: 22779 | U3: 26699 | V3: 10916 | W3: 12887 | X3: 569178 | Y3: 478228 | Z3: 462218 | AA3: 411254 | AB3: 298879 | AC3: 244991 | AD3: 206592 | AE3: 169258 | AF3: 140761 | AG3: 99546 | AH3: 81712 | AI3: 62256 | AJ3: 45517 | AK3: 29167 | AL3: 24683 | AM3: 12507 | AN3: 9984 | AO3: 1100749 | AP3: 896872 | AQ3: 802837 | AR3: 703054 | AS3: 541445 | AT3: 447132 | AU3: 371230 | AV3: 296145 | AW3: 254179 | AX3: 169998 | AY3: 149334 | AZ3: 104701 | BA3: 85251 | BB3: 51946 | BC3: 51382 | BD3: 23423 | BE3: 22871
A4: FEDERAL CAPITAL TERRITORY | B4: ABAJI | C4: Federal Capital Territory | D4: 2262531 | E4: 2572216 | F4: 4834747 | G4: 368062 | H4: 295804 | I4: 274169 | J4: 226094 | K4: 240570 | L4: 239062 | M4: 186691 | N4: 144517 | O4: 92826 | P4: 66230 | Q4: 38666 | R4: 33081 | S4: 18099 | T4: 16523 | U4: 10377 | V4: 6774 | W4: 4986 | X4: 366734 | Y4: 281057 | Z4: 232913 | AA4: 202152 | AB4: 248382 | AC4: 310563 | AD4: 263226 | AE4: 228757 | AF4: 148467 | AG4: 121262 | AH4: 62545 | AI4: 53076 | AJ4: 20135 | AK4: 16802 | AL4: 7187 | AM4: 5307 | AN4: 3651 | AO4: 734796 | AP4: 576861 | AQ4: 507082 | AR4: 428246 | AS4: 488952 | AT4: 549625 | AU4: 449917 | AV4: 373274 | AW4: 241293 | AX4: 187492 | AY4: 101211 | AZ4: 86157 | BA4: 38234 | BB4: 33325 | BC4: 17564 | BD4: 12081 | BE4: 8637
A5: KANO | B5: AJINGI | C5: Kano South | D5: 1991198 | E5: 2067531 | F5: 4058729 | G5: 387753 | H5: 322980 | I5: 227962 | J5: 200544 | K5: 177021 | L5: 146098 | M5: 130085 | N5: 90671 | O5: 87532 | P5: 50683 | Q5: 54767 | R5: 27118 | S5: 33549 | T5: 15389 | U5: 21368 | V5: 8085 | W5: 9593 | X5: 412439 | Y5: 340191 | Z5: 261361 | AA5: 214987 | AB5: 146611 | AC5: 127716 | AD5: 126706 | AE5: 100822 | AF5: 94047 | AG5: 58111 | AH5: 61392 | AI5: 31265 | AJ5: 36137 | AK5: 16043 | AL5: 22391 | AM5: 8246 | AN5: 9066 | AO5: 800192 | AP5: 663171 | AQ5: 489323 | AR5: 415531 | AS5: 323632 | AT5: 273814 | AU5: 256791 | AV5: 191493 | AW5: 181579 | AX5: 108794 | AY5: 116159 | AZ5: 58383 | BA5: 69686 | BB5: 31432 | BC5: 43759 | BD5: 16331 | BE5: 18659
A6: KANO | B6: BAGWAI | C6: Kano North | D6: 1707593 | E6: 1773259 | F6: 3480852 | G6: 337082 | H6: 269591 | I6: 198305 | J6: 173165 | K6: 145784 | L6: 123230 | M6: 108558 | N6: 79674 | O6: 74975 | P6: 45175 | Q6: 48347 | R6: 25108 | S6: 29568 | T6: 13848 | U6: 19406 | V6: 7538 | W6: 8239 | X6: 361310 | Y6: 289537 | Z6: 226417 | AA6: 185655 | AB6: 127262 | AC6: 108696 | AD6: 103576 | AE6: 84962 | AF6: 78255 | AG6: 51294 | AH6: 51932 | AI6: 26719 | AJ6: 30818 | AK6: 13574 | AL6: 18906 | AM6: 6791 | AN6: 7555 | AO6: 698392 | AP6: 559128 | AQ6: 424722 | AR6: 358820 | AS6: 273046 | AT6: 231926 | AU6: 212134 | AV6: 164636 | AW6: 153230 | AX6: 96469 | AY6: 100279 | AZ6: 51827 | BA6: 60386 | BB6: 27422 | BC6: 38312 | BD6: 14329 | BE6: 15794
A7: LAGOS | B7: EPE | C7: Lagos East | D7: 1641471 | E7: 1769815 | F7: 3411286 | G7: 217261 | H7: 184869 | I7: 184282 | J7: 168468 | K7: 164553 | L7: 152868 | M7: 131180 | N7: 115186 | O7: 83410 | P7: 68320 | Q7: 45950 | R7: 44942 | S7: 26090 | T7: 24529 | U7: 13565 | V7: 10049 | W7: 5949 | X7: 221755 | Y7: 183511 | Z7: 172987 | AA7: 171940 | AB7: 200414 | AC7: 191599 | AD7: 160579 | AE7: 141547 | AF7: 97953 | AG7: 77331 | AH7: 46783 | AI7: 42841 | AJ7: 21703 | AK7: 20107 | AL7: 9044 | AM7: 6694 | AN7: 3027 | AO7: 439016 | AP7: 368380 | AQ7: 357269 | AR7: 340408 | AS7: 364967 | AT7: 344467 | AU7: 291759 | AV7: 256733 | AW7: 181363 | AX7: 145651 | AY7: 92733 | AZ7: 87783 | BA7: 47793 | BB7: 44636 | BC7: 22609 | BD7: 16743 | BE7: 8976
A8: KADUNA | B8: JABA | C8: Kaduna South | D8: 1647823 | E8: 1684950 | F8: 3332773 | G8: 316448 | H8: 242337 | I8: 200951 | J8: 176560 | K8: 140498 | L8: 120827 | M8: 99100 | N8: 81212 | O8: 66365 | P8: 50063 | Q8: 38502 | R8: 36002 | S8: 24401 | T8: 21909 | U8: 15036 | V8: 10990 | W8: 6622 | X8: 329464 | Y8: 254826 | Z8: 212334 | AA8: 181775 | AB8: 134916 | AC8: 114893 | AD8: 102249 | AE8: 88239 | AF8: 70384 | AG8: 55155 | AH8: 40733 | AI8: 32938 | AJ8: 21421 | AK8: 18169 | AL8: 11804 | AM8: 9014 | AN8: 6636 | AO8: 645912 | AP8: 497163 | AQ8: 413285 | AR8: 358335 | AS8: 275414 | AT8: 235720 | AU8: 201349 | AV8: 169451 | AW8: 136749 | AX8: 105218 | AY8: 79235 | AZ8: 68940 | BA8: 45822 | BB8: 40078 | BC8: 26840 | BD8: 20004 | BE8: 13258
A9: OYO | B9: Atigbo | C9: Oyo North | D9: 1624418 | E9: 1689891 | F9: 3314309 | G9: 195475 | H9: 209362 | I9: 209644 | J9: 181590 | K9: 139963 | L9: 121042 | M9: 107780 | N9: 107465 | O9: 83131 | P9: 75945 | Q9: 50509 | R9: 50880 | S9: 30117 | T9: 29735 | U9: 14851 | V9: 10972 | W9: 5957 | X9: 204860 | Y9: 223989 | Z9: 226186 | AA9: 205895 | AB9: 168692 | AC9: 124578 | AD9: 101360 | AE9: 93544 | AF9: 85780 | AG9: 72084 | AH9: 56443 | AI9: 40237 | AJ9: 31047 | AK9: 24856 | AL9: 14833 | AM9: 9936 | AN9: 5571 | AO9: 400335 | AP9: 433351 | AQ9: 435830 | AR9: 387485 | AS9: 308655 | AT9: 245620 | AU9: 209140 | AV9: 201009 | AW9: 168911 | AX9: 148029 | AY9: 106952 | AZ9: 91117 | BA9: 61164 | BB9: 54591 | BC9: 29684 | BD9: 20908 | BE9: 11528
A10: RIVERS | B10: ABUA/ODUAL | C10: Rivers West | D10: 1582871 | E10: 1693254 | F10: 3276125 | G10: 183457 | H10: 195055 | I10: 200314 | J10: 184051 | K10: 139642 | L10: 119583 | M10: 106934 | N10: 103338 | O10: 82251 | P10: 73434 | Q10: 52340 | R10: 48500 | S10: 32556 | T10: 27762 | U10: 15732 | V10: 11637 | W10: 6285 | X10: 195266 | Y10: 211159 | Z10: 217097 | AA10: 207988 | AB10: 169491 | AC10: 130398 | AD10: 110499 | AE10: 95852 | AF10: 87600 | AG10: 73564 | AH10: 57817 | AI10: 43811 | AJ10: 35180 | AK10: 25218 | AL10: 16416 | AM10: 9832 | AN10: 6066 | AO10: 378723 | AP10: 406214 | AQ10: 417411 | AR10: 392039 | AS10: 309133 | AT10: 249981 | AU10: 217433 | AV10: 199190 | AW10: 169851 | AX10: 146998 | AY10: 110157 | AZ10: 92311 | BA10: 67736 | BB10: 52980 | BC10: 32148 | BD10: 21469 | BE10: 12351
A11: OYO | B11: AFIJIO | C11: Oyo Central | D11: 1588367 | E11: 1569248 | F11: 3157615 | G11: 196923 | H11: 198021 | I11: 200901 | J11: 166710 | K11: 131614 | L11: 119710 | M11: 105760 | N11: 99403 | O11: 80769 | P11: 72556 | Q11: 54254 | R11: 52772 | S11: 36407 | T11: 32443 | U11: 19208 | V11: 12704 | W11: 8212 | X11: 203793 | Y11: 201737 | Z11: 199439 | AA11: 177728 | AB11: 145933 | AC11: 119552 | AD11: 102112 | AE11: 92220 | AF11: 79061 | AG11: 67625 | AH11: 50732 | AI11: 43831 | AJ11: 30128 | AK11: 26289 | AL11: 14846 | AM11: 8998 | AN11: 5224 | AO11: 400716 | AP11: 399758 | AQ11: 400340 | AR11: 344438 | AS11: 277547 | AT11: 239262 | AU11: 207872 | AV11: 191623 | AW11: 159830 | AX11: 140181 | AY11: 104986 | AZ11: 96603 | BA11: 66535 | BB11: 58732 | BC11: 34054 | BD11: 21702 | BE11: 13436
A12: KATSINA | B12: BAURE | C12: Katsina North | D12: 1389506 | E12: 1435175 | F12: 2824681 | G12: 279062 | H12: 213008 | I12: 165435 | J12: 142000 | K12: 117831 | L12: 101715 | M12: 86514 | N12: 66956 | O12: 57793 | P12: 39702 | Q12: 36215 | R12: 22767 | S12: 23366 | T12: 12549 | U12: 12989 | V12: 6594 | W12: 5010 | X12: 300420 | Y12: 229160 | Z12: 178458 | AA12: 145141 | AB12: 105280 | AC12: 90829 | AD12: 86051 | AE12: 72362 | AF12: 62454 | AG12: 44694 | AH12: 39273 | AI12: 22628 | AJ12: 22709 | AK12: 11391 | AL12: 13055 | AM12: 6324 | AN12: 4946 | AO12: 579482 | AP12: 442168 | AQ12: 343893 | AR12: 287141 | AS12: 223111 | AT12: 192544 | AU12: 172565 | AV12: 139318 | AW12: 120247 | AX12: 84396 | AY12: 75488 | AZ12: 45395 | BA12: 46075 | BB12: 23940 | BC12: 26044 | BD12: 12918 | BE12: 9956
A13: KADUNA | B13: IKARA | C13: Kaduna North | D13: 1340543 | E13: 1383402 | F13: 2723945 | G13: 260449 | H13: 208547 | I13: 162668 | J13: 144893 | K13: 120662 | L13: 97771 | M13: 80946 | N13: 62109 | O13: 53809 | P13: 36574 | Q13: 33745 | R13: 22137 | S13: 19523 | T13: 12386 | U13: 12555 | V13: 6055 | W13: 5714 | X13: 267061 | Y13: 213830 | Z13: 176289 | AA13: 147931 | AB13: 112621 | AC13: 96970 | AD13: 83651 | AE13: 69930 | AF13: 57491 | AG13: 42128 | AH13: 34793 | AI13: 25924 | AJ13: 19562 | AK13: 12989 | AL13: 11346 | AM13: 6001 | AN13: 4885 | AO13: 527510 | AP13: 422377 | AQ13: 338957 | AR13: 292824 | AS13: 233283 | AT13: 194741 | AU13: 164597 | AV13: 132039 | AW13: 111300 | AX13: 78702 | AY13: 68538 | AZ13: 48061 | BA13: 39085 | BB13: 25375 | BC13: 23901 | BD13: 12056 | BE13: 10599
... A110: BAYELSA | B110: BRASS | C110: Bayelsa East | D110: 237154 | E110: 247846 | F110: 485000 | G110: 28291 | H110: 30157 | I110: 30565 | J110: 28300 | K110: 20369 | L110: 17445 | M110: 15851 | N110: 15417 | O110: 12363 | P110: 10889 | Q110: 7633 | R110: 6750 | S110: 5076 | T110: 3645 | U110: 1931 | V110: 1673 | W110: 799 | X110: 29482 | Y110: 31974 | Z110: 32491 | AA110: 31496 | AB110: 24165 | AC110: 18084 | AD110: 15179 | AE110: 13626 | AF110: 12632 | AG110: 10582 | AH110: 8305 | AI110: 6346 | AJ110: 5007 | AK110: 3713 | AL110: 2423 | AM110: 1542 | AN110: 799 | AO110: 57773 | AP110: 62131 | AQ110: 63056 | AR110: 59796 | AS110: 44534 | AT110: 35529 | AU110: 31030 | AV110: 29043 | AW110: 24995 | AX110: 21471 | AY110: 15938 | AZ110: 13096 | BA110: 10083 | BB110: 7358 | BC110: 4354 | BD110: 3215 | BE110: 1598

Sheet Metadata
A1: Item | B1: Metadata
A2: Country | B2: Nigeria
A3: Basline population | B3: 2006 Census
A4: Reference year of projections | B4: 2020
A5: Source(s) | B5: United States Cenus Bureau - PEPFAR progrram
B6: https://www.census.gov/geographies/mapping-files/time-series/demo/international-programs/subnationalpopulation.html
A7: Methods | B7: https://www2.census.gov/programs-surveys/international-programs/about/global-mapping/subntl-pop-est-methods-pgs-uscb-dec16.pdf
A8: Year of publication | B8: 2016
A9: ADM1 Name | B9: State and Territory
A10: # of ADM1 units | B10: 37
A11: Age- and Sex disaggregation | B11: 5-year age groups, male, female, SAD integrated
A12: Open-ended group | B12: 80+
A13: ADM2 Name | B13: Local Government Area
A14: # of ADM2 unites | B14: 773
A15: Age- and Sex disaggregation | B15: 5-year age groups, male, female, SAD integrated
A16: Open-ended group | B16: 80+
A17: Limitations of use and general Notes
A23: =SUM('Age groupings population'!#REF!) -> #REF!
A24: =SUM(NGA_ADM2_POP_2020!G:G) -> 218521350
A25: =A24-A23 -> #REF!

Sheet States Lands&Popu
A1: admin1Name_en | B1: admin1RefName | C1: Shape_Length | D1: Shape_Area | E1: Total land mass | F1: Female | G1: Male | H1: Total_Population
A2: Abia | B2: Abia | C2: 4.695135 | D2: 0.396543 | E2: =SUM(C2:D2) -> 5.091678 | F2: =SUBTOTAL(9,'Age groupings population'!D461:D753) -> 895663 | G2: =SUBTOTAL(9,'Age groupings population'!E461:E753) -> 897361 | H2: =SUB(F2:G2) -> #NAME?
A3: Adamawa | B3: Adamawa | C3: 11.525443 | D3: 3.113007 | E3: =SUM(C3:D3) -> 14.63845 | F3: =SUBTOTAL(9,'Age groupings population'!D414:D771) -> 1041814 | G3: =SUBTOTAL(9,'Age groupings population'!E414:E771) -> 1046765
A4: Akwa Ibom | B4: Akwa Ibom | C4: 5.26383 | D4: 0.549476 | E4: =SUM(C4:D4) -> 5.813306 | F4: =SUBTOTAL(9,'Age groupings population'!D93:D763) -> 2387475 | G4: =SUBTOTAL(9,'Age groupings population'!E93:E763) -> 2406927
A5: Anambra | B5: Anambra | C5: 3.59596 | D5: 0.392661 | E5: =SUM(C5:D5) -> 3.988621 | F5: =SUBTOTAL(9,'Age groupings population'!D413:D610) -> 809588 | G5: =SUBTOTAL(9,'Age groupings population'!E413:E610) -> 814316
A6: Bauchi | B6: Bauchi | C6: 13.952005 | D6: 4.011018 | E6: =SUM(C6:D6) -> 17.963023 | F6: =SUBTOTAL(9,'Age groupings population'!D435:D702) -> 781971 | G6: =SUBTOTAL(9,'Age groupings population'!E435:E702) -> 782128
A7: Bayelsa | B7: Bayelsa | C7: 5.046708 | D7: 0.776768 | E7: =SUM(C7:D7) -> 5.823476 | F7: =SUBTOTAL(9,'Age groupings population'!D524:D691) -> 406811 | G7: =SUBTOTAL(9,'Age groupings population'!E524:E691) -> 403196
A8: Benue | B8: Benue | C8: 9.40808 | D8: 2.578363 | E8: =SUM(C8:D8) -> 11.986443 | F8: =SUBTOTAL(9,'Age groupings population'!D428:D738) -> 895663 | G8: =SUBTOTAL(9,'Age groupings population'!E428:E738) -> 897361
A9: Borno | B9: Borno | C9: 13.714364 | D9: 5.987849 | E9: =SUM(C9:D9) -> 19.702213 | F9: 1166632 | G9: 1249801
A10: Cross River | B10: Cross River | C10: 8.779796 | D10: 1.711218 | E10: =SUM(C10:D10) -> 10.491014 | F10: =SUBTOTAL(9,'Age groupings population'!D410:D752) -> 1000969 | G10: =SUBTOTAL(9,'Age groupings population'!E410:E752) -> 1004544
A11: Delta | B11: Delta | C11: 7.372526 | D11: 1.394082 | E11: =SUM(C11:D11) -> 8.766608 | F11: =SUBTOTAL(9,'Age groupings population'!D424:D758) -> 1041814 | G11: =SUBTOTAL(9,'Age groupings population'!E424:E758) -> 1046765
A12: Ebonyi | B12: Ebonyi | C12: 4.489355 | D12: 0.51805 | E12: =SUM(C12:D12) -> 5.007405 | F12: 1523899 | G12: 1459234
A13: Edo | B13: Edo | C13: 7.889425 | D13: 1.595809 | E13: =SUM(C13:D13) -> 9.485234 | F13: 2174346 | G13: 2218724
A14: Ekiti | B14: Ekiti | C14: 3.395633 | D14: 0.471634 | E14: =SUM(C14:D14) -> 3.867267 | F14: 1740362 | G14: 1770590
A15: Enugu | B15: Enugu | C15: 4.319893 | D15: 0.624323 | E15: =SUM(C15:D15) -> 4.944216
A16: Federal Capital Territory | B16: Federal Capital Territory | C16: 3.498412 | D16: 0.607222 | E16: =SUM(C16:D16) -> 4.105634
A17: Gombe | B17: Gombe | C17: 5.955286 | D17: 1.438747 | E17: =SUM(C17:D17) -> 7.394033
A18: Imo | B18: Imo | C18: 2.878088 | D18: 0.414097 | E18: =SUM(C18:D18) -> 3.292185
A19: Jigawa | B19: Jigawa | C19: 11.771497 | D19: 1.928873 | E19: =SUM(C19:D19) -> 13.70037
A20: Kaduna | B20: Kaduna | C20: 12.613678 | D20: 3.645639 | E20: =SUM(C20:D20) -> 16.259317
A21: Kano | B21: Kano | C21: 8.244195 | D21: 1.685607 | E21: =SUM(C21:D21) -> 9.929802
A22: Katsina | B22: Katsina | C22: 9.105637 | D22: 1.991947 | E22: =SUM(C22:D22) -> 11.097584
A23: Kebbi | B23: Kebbi | C23: 14.968981 | D23: 3.035227 | E23: =SUM(C23:D23) -> 18.004208
A24: Kogi | B24: Kogi | C24: 10.476383 | D24: 2.368882 | E24: =SUM(C24:D24) -> 12.845265
A25: Kwara | B25: Kwara | C25: 12.046963 | D25: 2.766244 | E25: =SUM(C25:D25) -> 14.813207
A26: Lagos | B26: Lagos | C26: 4.28777 | D26: 0.300166 | E26: =SUM(C26:D26) -> 4.587936
... A38: Zamfara | B38: Zamfara | C38: 9.466144 | D38: 2.782855 | E38: =SUM(C38:D38) -> 12.248999

Sheet Cross river Land
A1: admin2Name_en | B1: admin2Pcode | C1: CODPSMATCH | D1: admin2RefName | E1: admin2AltName1_en | F1: SenDist_en | G1: SenDistPcode | H1: admin1Name_en | I1: date | J1: validOn | K1: Shape_Length | L1: Shape_Area
A2: Aba North | B2: NG001001 | C2: =COUNTIF(NGA_ADM2_POP_2020!C:C,'Cross river Land'!B2) -> 1 | D2: Aba North | E2: <Null> | F2: Abia South | G2: NG00103 | H2: Abia | I2: 42703 | J2: 43572 | K2: 0.237074 | L2: 0.001524
A3: Aba South | B3: NG001002 | C3: =COUNTIF(NGA_ADM2_POP_2020!C:C,'Cross river Land'!B3) -> 1 | D3: Aba South | E3: <Null> | F3: Abia South | G3: NG00103 | H3: Abia | I3: 42703 | J3: 43572 | K3: 0.262477 | L3: 0.003531
A4: Arochukwu | B4: NG001003 | C4: =COUNTIF(NGA_ADM2_POP_2020!C:C,'Cross river Land'!B4) -> 1 | D4: Arochukwu | E4: <Null> | F4: Abia North | G4: NG00102 | H4: Abia | I4: 42703 | J4: 43572 | K4: 1.263424 | L4: 0.042547
A5: Bende | B5: NG001004 | C5: =COUNTIF(NGA_ADM2_POP_2020!C:C,'Cross river Land'!B5) -> 1 | D5: Bende | E5: <Null> | F5: Abia North | G5: NG00102 | H5: Abia | I5: 42703 | J5: 43572 | K5: 1.36038 | L5: 0.050513
A6: Ikwuano | B6: NG001005 | C6: =COUNTIF(NGA_ADM2_POP_2020!C:C,'Cross river Land'!B6) -> 1 | D6: Ikwuano | E6: <Null> | F6: Abia Central | G6: NG00101 | H6: Abia | I6: 42703 | J6: 43572 | K6: 0.752887 | L6: 0.022714
A7: Isiala-Ngwa North | B7: NG001006 | C7: =COUNTIF(NGA_ADM2_POP_2020!C:C,'Cross river Land'!B7) -> 1 | D7: Isiala-Ngwa North | E7: <Null> | F7: Abia Central | G7: NG00101 | H7: Abia | I7: 42703 | J7: 43572 | K7: 0.863972 | L7: 0.023132
A8: Isiala-Ngwa South | B8: NG001007 | C8: =COUNTIF(NGA_ADM2_POP_2020!C:C,'Cross river Land'!B8) -> 1 | D8: Isiala-Ngwa South | E8: <Null> | F8: Abia Central | G8: NG00101 | H8: Abia | I8: 42703 | J8: 43572 | K8: 0.918367 | L8: 0.022604
A9: Isiukwuato | B9: NG001008 | C9: =COUNTIF(NGA_ADM2_POP_2020!C:C,'Cross river Land'!B9) -> 1 | D9: Isiukwuato | E9: <Null> | F9: Abia North | G9: NG00102 | H9: Abia | I9: 42703 | J9: 43572 | K9: 0.775927 | L9: 0.031235
A10: Obi Ngwa | B10: NG001009 | C10: =COUNTIF(NGA_ADM2_POP_2020!C:C,'Cross river Land'!B10) -> 1 | D10: Obi Ngwa | E10: <Null> | F10: Abia South | G10: NG00103 | H10: Abia | I10: 42703 | J10: 43572 | K10: 0.877278 | L10: 0.032944
A11: Ohafia | B11: NG001010 | C11: =COUNTIF(NGA_ADM2_POP_2020!C:C,'Cross river Land'!B11) -> 1 | D11: Ohafia | E11: <Null> | F11: Abia North | G11: NG00102 | H11: Abia | I11: 42703 | J11: 43572 | K11: 0.946686 | L11: 0.035926
A12: Osisioma Ngwa | B12: NG001011 | C12: =COUNTIF(NGA_ADM2_POP_2020!C:C,'Cross river Land'!B12) -> 1 | D12: Osisioma Ngwa | E12: <Null> | F12: Abia South | G12: NG00103 | H12: Abia | I12: 42703 | J12: 43572 | K12: 0.604804 | L12: 0.014254
A13: Ugwunagbo | B13: NG001012 | C13: =COUNTIF(NGA_ADM2_POP_2020!C:C,'Cross river Land'!B13) -> 1 | D13: Ugwunagbo | E13: <Null> | F13: Abia South | G13: NG00103 | H13: Abia | I13: 42703 | J13: 43572 | K13: 0.49429 | L13: 0.010274
... A775: Zurmi | B775: NG037014 | C775: =COUNTIF(NGA_ADM2_POP_2020!C:C,'Cross river Land'!B775) -> 1 | D775: Zurmi | E775: <Null> | F775: Zamfara North | G775: NG03702 | H775: Zamfara | I775: 42703 | J775: 43572 | K775: 2.611934 | L775: 0.223538
K776: =SUM(K170:K187) -> 26.244799 | L776: =SUM(L170:L187) -> 1.711217
L779: Total Landmass
L780: =SUM(K776:L776) -> 27.956016

Sheet NGA_ADM2_POP_2020
A1: ADM1_NAME | B1: ADM2_NAME | C1: ADM2_PCODE | D1: UNIQUE | E1: F_TL | F1: M_TL | G1: T_TL | H1: F_00_04 | I1: F_05_09 | J1: F_10_14 | K1: F_15_19 | L1: F_20_24 | M1: F_25_29 | N1: F_30_34 | O1: F_35_39 | P1: F_40_44 | Q1: F_45_49 | R1: F_50_54 | S1: F_55_59 | T1: F_60_64 | U1: F_65_69 | V1: F_70_74 | W1: F_75_79 | X1: F_80Plus | Y1: M_00_04 | Z1: M_05_09 | AA1: M_10_14 | AB1: M_15_19 | AC1: M_20_24 | AD1: M_25_29 | AE1: M_30_34 | AF1: M_35_39 | AG1: M_40_44 | AH1: M_45_49 | AI1: M_50_54 | AJ1: M_55_59 | AK1: M_60_64 | AL1: M_65_69 | AM1: M_70_74 | AN1: M_75_79 | AO1: M_80Plus | AP1: T_00_04 | AQ1: T_05_09 | AR1: T_10_14 | AS1: T_15_19 | AT1: T_20_24 | AU1: T_25_29 | AV1: T_30_34 | AW1: T_35_39 | AX1: T_40_44 | AY1: T_45_49 | AZ1: T_50_54 | BA1: T_55_59 | BB1: T_60_64 | BC1: T_65_69 | BD1: T_70_74 | BE1: T_75_79 | BF1: T_80Plus
A2: ABIA | B2: ABA NORTH | C2: =VLOOKUP(B2,'Cross river Land'!A:B,2,0) -> NG001001 | D2: =COUNTIF(C:C,C2) -> 1 | E2: 57686 | F2: 57619 | G2: 115305 | H2: 6388 | I2: 5977 | J2: 7828 | K2: 7206 | L2: 5964 | M2: 4996 | N2: 4249 | O2: 3896 | P2: 2843 | Q2: 2483 | R2: 1641 | S2: 1517 | T2: 935 | U2: 828 | V2: 443 | W2: 315 | X2: 177 | Y2: 6624 | Z2: 5870 | AA2: 6606 | AB2: 6046 | AC2: 5819 | AD2: 4994 | AE2: 4586 | AF2: 3865 | AG2: 3571 | AH2: 3160 | AI2: 2061 | AJ2: 1845 | AK2: 907 | AL2: 911 | AM2: 374 | AN2: 277 | AO2: 103 | AP2: 13012 | AQ2: 11847 | AR2: 14434 | AS2: 13252 | AT2: 11783 | AU2: 9990 | AV2: 8835 | AW2: 7761 | AX2: 6414 | AY2: 5643 | AZ2: 3702 | BA2: 3362 | BB2: 1842 | BC2: 1739 | BD2: 817 | BE2: 592 | BF2: 280
A3: ABIA | B3: ABA SOUTH | C3: =VLOOKUP(B3,'Cross river Land'!A:B,2,0) -> NG001002 | D3: =COUNTIF(C:C,C3) -> 1 | E3: 185314 | F3: 199626 | G3: 384940 | H3: 19222 | I3: 20744 | J3: 24907 | K3: 23586 | L3: 18694 | M3: 15988 | N3: 13318 | O3: 12485 | P3: 9173 | Q3: 8381 | R3: 5613 | S3: 5142 | T3: 2834 | U3: 2467 | V3: 1239 | W3: 986 | X3: 535 | Y3: 20579 | Z3: 21416 | AA3: 24319 | AB3: 24659 | AC3: 21072 | AD3: 17262 | AE3: 14268 | AF3: 12228 | AG3: 11039 | AH3: 9561 | AI3: 7101 | AJ3: 6022 | AK3: 3828 | AL3: 3118 | AM3: 1644 | AN3: 1020 | AO3: 490 | AP3: 39801 | AQ3: 42160 | AR3: 49226 | AS3: 48245 | AT3: 39766 | AU3: 33250 | AV3: 27586 | AW3: 24713 | AX3: 20212 | AY3: 17942 | AZ3: 12714 | BA3: 11164 | BB3: 6662 | BC3: 5585 | BD3: 2883 | BE3: 2006 | BF3: 1025
A4: ABIA | B4: AROCHUKWU | C4: =VLOOKUP(B4,'Cross river Land'!A:B,2,0) -> NG001003 | D4: =COUNTIF(C:C,C4) -> 1 | E4: 126730 | F4: 128709 | G4: 255439 | H4: 13544 | I4: 14969 | J4: 15892 | K4: 15049 | L4: 10955 | M4: 9022 | N4: 8242 | O4: 8102 | P4: 6759 | Q4: 6111 | R4: 4644 | S4: 4393 | T4: 3054 | U4: 2717 | V4: 1568 | W4: 1065 | X4: 644 | Y4: 14374 | Z4: 16017 | AA4: 17151 | AB4: 16624 | AC4: 12964 | AD4: 9550 | AE4: 7395 | AF4: 6701 | AG4: 6198 | AH4: 5546 | AI4: 4397 | AJ4: 3689 | AK4: 2579 | AL4: 2452 | AM4: 1407 | AN4: 1179 | AO4: 486 | AP4: 27918 | AQ4: 30986 | AR4: 33043 | AS4: 31673 | AT4: 23919 | AU4: 18572 | AV4: 15637 | AW4: 14803 | AX4: 12957 | AY4: 11657 | AZ4: 9041 | BA4: 8082 | BB4: 5633 | BC4: 5169 | BD4: 2975 | BE4: 2244 | BF4: 1130
A5: ABIA | B5: BENDE | C5: =VLOOKUP(B5,'Cross river Land'!A:B,2,0) -> NG001004 | D5: =COUNTIF(C:C,C5) -> 1 | E5: 124460 | F5: 120035 | G5: 244495 | H5: 13473 | I5: 13602 | J5: 14501 | K5: 13798 | L5: 9908 | M5: 8153 | N5: 7678 | O5: 7475 | P5: 6353 | Q5: 6221 | R5: 5070 | S5: 5135 | T5: 3817 | U5: 4021 | V5: 2598 | W5: 1788 | X5: 869 | Y5: 13632 | Z5: 14335 | AA5: 15180 | AB5: 14995 | AC5: 11648 | AD5: 8674 | AE5: 7119 | AF5: 6164 | AG5: 5804 | AH5: 5368 | AI5: 3973 | AJ5: 4150 | AK5: 2546 | AL5: 2993 | AM5: 1523 | AN5: 1315 | AO5: 616 | AP5: 27105 | AQ5: 27937 | AR5: 29681 | AS5: 28793 | AT5: 21556 | AU5: 16827 | AV5: 14797 | AW5: 13639 | AX5: 12157 | AY5: 11589 | AZ5: 9043 | BA5: 9285 | BB5: 6363 | BC5: 7014 | BD5: 4121 | BE5: 3103 | BF5: 1485
A6: ABIA | B6: IKWUANO | C6: =VLOOKUP(B6,'Cross river Land'!A:B,2,0) -> NG001005 | D6: =COUNTIF(C:C,C6) -> 1 | E6: 155278 | F6: 161525 | G6: 316803 | H6: 16378 | I6: 18303 | J6: 19019 | K6: 19069 | L6: 15232 | M6: 11109 | N6: 9742 | O6: 9133 | P6: 7577 | Q6: 7187 | R6: 5489 | S6: 5428 | T6: 3637 | U6: 3631 | V6: 2104 | W6: 1414 | X6: 826 | Y6: 16909 | Z6: 18989 | AA6: 20743 | AB6: 20924 | AC6: 20270 | AD6: 12862 | AE6: 9060 | AF6: 7906 | AG6: 7285 | AH6: 6483 | AI6: 4938 | AJ6: 5091 | AK6: 3138 | AL6: 3092 | AM6: 1822 | AN6: 1365 | AO6: 648 | AP6: 33287 | AQ6: 37292 | AR6: 39762 | AS6: 39993 | AT6: 35502 | AU6: 23971 | AV6: 18802 | AW6: 17039 | AX6: 14862 | AY6: 13670 | AZ6: 10427 | BA6: 10519 | BB6: 6775 | BC6: 6723 | BD6: 3926 | BE6: 2779 | BF6: 1474
A7: ABIA | B7: Isiala-Ngwa North | C7: =VLOOKUP(B7,'Cross river Land'!A:B,2,0) -> NG001006 | D7: =COUNTIF(C:C,C7) -> 1 | E7: 112642 | F7: 108993 | G7: 221635 | H7: 12122 | I7: 12698 | J7: 14546 | K7: 13791 | L7: 9362 | M7: 7858 | N7: 7100 | O7: 6799 | P7: 5772 | Q7: 5205 | R7: 4287 | S7: 3878 | T7: 2737 | U7: 2556 | V7: 1984 | W7: 1118 | X7: 829 | Y7: 12596 | Z7: 13190 | AA7: 14682 | AB7: 14187 | AC7: 10438 | AD7: 7669 | AE7: 6249 | AF7: 5570 | AG7: 5138 | AH7: 4599 | AI7: 3757 | AJ7: 3456 | AK7: 2204 | AL7: 2158 | AM7: 1441 | AN7: 1075 | AO7: 584 | AP7: 24718 | AQ7: 25888 | AR7: 29228 | AS7: 27978 | AT7: 19800 | AU7: 15527 | AV7: 13349 | AW7: 12369 | AX7: 10910 | AY7: 9804 | AZ7: 8044 | BA7: 7334 | BB7: 4941 | BC7: 4714 | BD7: 3425 | BE7: 2193 | BF7: 1413
A8: ABIA | B8: Isiala-Ngwa South | C8: =VLOOKUP(B8,'Cross river Land'!A:B,2,0) -> NG001007 | D8: =COUNTIF(C:C,C8) -> 1 | E8: 84520 | F8: 80615 | G8: 165135 | H8: 9523 | I8: 9062 | J8: 11124 | K8: 10189 | L8: 7055 | M8: 5705 | N8: 5160 | O8: 4907 | P8: 4335 | Q8: 3745 | R8: 3434 | S8: 3005 | T8: 2452 | U8: 1800 | V8: 1362 | W8: 914 | X8: 748 | Y8: 9746 | Z8: 9383 | AA8: 11724 | AB8: 10225 | AC8: 7117 | AD8: 5385 | AE8: 4768 | AF8: 4161 | AG8: 4044 | AH8: 3371 | AI8: 2718 | AJ8: 2408 | AK8: 1710 | AL8: 1475 | AM8: 1060 | AN8: 833 | AO8: 487 | AP8: 19269 | AQ8: 18445 | AR8: 22848 | AS8: 20414 | AT8: 14172 | AU8: 11090 | AV8: 9928 | AW8: 9068 | AX8: 8379 | AY8: 7116 | AZ8: 6152 | BA8: 5413 | BB8: 4162 | BC8: 3275 | BD8: 2422 | BE8: 1747 | BF8: 1235
A9: ABIA | B9: Isiukwuato | C9: =VLOOKUP(B9,'Cross river Land'!A:B,2,0) -> NG001008 | D9: =COUNTIF(C:C,C9) -> 1 | E9: 93491 | F9: 87572 | G9: 181063 | H9: 8525 | I9: 8746 | J9: 11130 | K9: 12206 | L9: 10032 | M9: 5871 | N9: 4877 | O9: 4773 | P9: 4335 | Q9: 4240 | R9: 3755 | S9: 4095 | T9: 3161 | U9: 3373 | V9: 2045 | W9: 1511 | X9: 816 | Y9: 8511 | Z9: 8910 | AA9: 11734 | AB9: 12210 | AC9: 10640 | AD9: 6711 | AE9: 4747 | AF9: 4079 | AG9: 3804 | AH9: 3621 | AI9: 2718 | AJ9: 2924 | AK9: 1979 | AL9: 2064 | AM9: 1316 | AN9: 1101 | AO9: 503 | AP9: 17036 | AQ9: 17656 | AR9: 22864 | AS9: 24416 | AT9: 20672 | AU9: 12582 | AV9: 9624 | AW9: 8852 | AX9: 8139 | AY9: 7861 | AZ9: 6473 | BA9: 7019 | BB9: 5140 | BC9: 5437 | BD9: 3361 | BE9: 2612 | BF9: 1319
A10: ABIA | B10: Obi Ngwa | C10: =VLOOKUP(B10,'Cross river Land'!A:B,2,0) -> NG001009 | D10: =COUNTIF(C:C,C10) -> 1 | E10: 121537 | F10: 116490 | G10: 238027 | H10: 13615 | I10: 13484 | J10: 16478 | K10: 14886 | L10: 10425 | M10: 8067 | N10: 7479 | O10: 6939 | P10: 6232 | Q10: 5514 | R10: 4552 | S10: 3785 | T10: 3208 | U10: 2504 | V10: 2055 | W10: 1274 | X10: 1040 | Y10: 13642 | Z10: 13960 | AA10: 16062 | AB10: 14501 | AC10: 10768 | AD10: 8067 | AE10: 6863 | AF10: 5791 | AG10: 5772 | AH10: 5263 | AI10: 4120 | AJ10: 3616 | AK10: 2563 | AL10: 2222 | AM10: 1533 | AN10: 1046 | AO10: 701 | AP10: 27257 | AQ10: 27444 | AR10: 32540 | AS10: 29387 | AT10: 21193 | AU10: 16134 | AV10: 14342 | AW10: 12730 | AX10: 12004 | AY10: 10777 | AZ10: 8672 | BA10: 7401 | BB10: 5771 | BC10: 4726 | BD10: 3588 | BE10: 2320 | BF10: 1741
A11: ABIA | B11: OHAFIA | C11: =VLOOKUP(B11,'Cross river Land'!A:B,2,0) -> NG001010 | D11: =COUNTIF(C:C,C11) -> 1 | E11: 176085 | F11: 177797 | G11: 353882 | H11: 19431 | I11: 20452 | J11: 21995 | K11: 20914 | L11: 14677 | M11: 12154 | N11: 11006 | O11: 11002 | P11: 9056 | Q11: 8479 | R11: 6370 | S11: 6527 | T11: 4151 | U11: 3993 | V11: 2696 | W11: 2117 | X11: 1065 | Y11: 20654 | Z11: 21767 | AA11: 24353 | AB11: 23893 | AC11: 17072 | AD11: 12733 | AE11: 10064 | AF11: 9080 | AG11: 8350 | AH11: 7490 | AI11: 5664 | AJ11: 5486 | AK11: 3339 | AL11: 3320 | AM11: 2118 | AN11: 1604 | AO11: 810 | AP11: 40085 | AQ11: 42219 | AR11: 46348 | AS11: 44807 | AT11: 31749 | AU11: 24887 | AV11: 21070 | AW11: 20082 | AX11: 17406 | AY11: 15969 | AZ11: 12034 | BA11: 12013 | BB11: 7490 | BC11: 7313 | BD11: 4814 | BE11: 3721 | BF11: 1875
A12: ABIA | B12: OSISIOMA NGWA | C12: =VLOOKUP(B12,'Cross river Land'!A:B,2,0) -> NG001011 | D12: =COUNTIF(C:C,C12) -> 1 | E12: 143335 | F12: 145419 | G12: 288754 | H12: 17830 | I12: 15892 | J12: 19286 | K12: 17189 | L12: 13810 | M12: 11661 | N12: 9932 | O12: 8861 | P12: 6845 | Q12: 5787 | R12: 4245 | S12: 4076 | T12: 2674 | U12: 2083 | V12: 1363 | W12: 1075 | X12: 726 | Y12: 19000 | Z12: 16229 | AA12: 17748 | AB12: 16401 | AC12: 14294 | AD12: 11821 | AE12: 10432 | AF12: 8764 | AG12: 8056 | AH12: 6829 | AI12: 4956 | AJ12: 4043 | AK12: 2293 | AL12: 2078 | AM12: 1139 | AN12: 869 | AO12: 467 | AP12: 36830 | AQ12: 32121 | AR12: 37034 | AS12: 33590 | AT12: 28104 | AU12: 23482 | AV12: 20364 | AW12: 17625 | AX12: 14901 | AY12: 12616 | AZ12: 9201 | BA12: 8119 | BB12: 4967 | BC12: 4161 | BD12: 2502 | BE12: 1944 | BF12: 1193
A13: ABIA | B13: UGWUNAGBO | C13: =VLOOKUP(B13,'Cross river Land'!A:B,2,0) -> NG001012 | D13: =COUNTIF(C:C,C13) -> 1 | E13: 55827 | F13: 55886 | G13: 111713 | H13: 6639 | I13: 6796 | J13: 7135 | K13: 6971 | L13: 4795 | M13: 4033 | N13: 3607 | O13: 3395 | P13: 2717 | Q13: 2503 | R13: 1923 | S13: 1653 | T13: 1106 | U13: 1108 | V13: 653 | W13: 471 | X13: 322 | Y13: 6747 | Z13: 6956 | AA13: 7523 | AB13: 7059 | AC13: 5352 | AD13: 4034 | AE13: 3415 | AF13: 2992 | AG13: 2798 | AH13: 2390 | AI13: 1891 | AJ13: 1540 | AK13: 1169 | AL13: 929 | AM13: 509 | AN13: 363 | AO13: 219 | AP13: 13386 | AQ13: 13752 | AR13: 14658 | AS13: 14030 | AT13: 10147 | AU13: 8067 | AV13: 7022 | AW13: 6387 | AX13: 5515 | AY13: 4893 | AZ13: 3814 | BA13: 3193 | BB13: 2275 | BC13: 2037 | BD13: 1162 | BE13: 834 | BF13: 541
... A399: KANO | B399: MINJIBIR | C399: =VLOOKUP(B399,'Cross river Land'!A:B,2,0) -> NG020030 | D399: =COUNTIF(C:C,C399) -> 1 | E399: 152314 | F399: 148427 | G399: 300741 | H399: 29601 | I399: 24501 | J399: 16971 | K399: 15531 | L399: 12814 | M399: 10933 | N399: 9778 | O399: 7243 | P399: 6854 | Q399: 3955 | R399: 4304 | S399: 2323 | T399: 2736 | U399: 1402 | V399: 1896 | W399: 677 | X399: 795 | Y399: 31593 | Z399: 24329 | AA399: 17114 | AB399: 13941 | AC399: 9506 | AD399: 8951 | AE399: 8825 | AF399: 7518 | AG399: 6987 | AH399: 4638 | AI399: 4658 | AJ399: 2875 | AK399: 2878 | AL399: 1406 | AM399: 1882 | AN399: 669 | AO399: 657 | AP399: 61194 | AQ399: 48830 | AR399: 34085 | AS399: 29472 | AT399: 22320 | AU399: 19884 | AV399: 18603 | AW399: 14761 | AX399: 13841 | AY399: 8593 | AZ399: 8962 | BA399: 5198 | BB399: 5614 | BC399: 2808 | BD399: 3778 | BE399: 1346 | BF399: 1452
A400: KANO | B400: NASSARAWA | C400: NG020031 | D400: =COUNTIF(C:C,C400) -> 1 | E400: 467494 | F400: 565158 | G400: 1032652 | H400: 90480 | I400: 72114 | J400: 62452 | K400: 48217 | L400: 41026 | M400: 35580 | N400: 28051 | O400: 22510 | P400: 19499 | Q400: 12169 | R400: 10890 | S400: 7367 | T400: 5979 | U400: 3695 | V400: 3676 | W400: 1790 | X400: 1999 | Y400: 96121 | Z400: 77751 | AA400: 76169 | AB400: 65530 | AC400: 50627 | AD400: 43578 | AE400: 35889 | AF400: 30486 | AG400: 24169 | AH400: 18639 | AI400: 14078 | AJ400: 12616 | AK400: 7114 | AL400: 5568 | AM400: 3403 | AN400: 2078 | AO400: 1342 | AP400: 186601 | AQ400: 149865 | AR400: 138621 | AS400: 113747 | AT400: 91653 | AU400: 79158 | AV400: 63940 | AW400: 52996 | AX400: 43668 | AY400: 30808 | AZ400: 24968 | BA400: 19983 | BB400: 13093 | BC400: 9263 | BD400: 7079 | BE400: 3868 | BF400: 3341
A401: KANO | B401: RANO | C401: =VLOOKUP(B401,'Cross river Land'!A:B,2,0) -> NG020032 | D401: =COUNTIF(C:C,C401) -> 1 | E401: 110725 | F401: 117271 | G401: 227996 | H401: 22758 | I401: 18114 | J401: 12579 | K401: 10723 | L401: 9575 | M401: 7966 | N401: 7125 | O401: 4973 | P401: 4723 | Q401: 2921 | R401: 3047 | S401: 1408 | T401: 1985 | U401: 766 | V401: 1196 | W401: 386 | X401: 480 | Y401: 23803 | Z401: 19607 | AA401: 14855 | AB401: 12378 | AC401: 8753 | AD401: 7248 | AE401: 6817 | AF401: 5687 | AG401: 5100 | AH401: 3338 | AI401: 3273 | AJ401: 1664 | AK401: 1954 | AL401: 820 | AM401: 1112 | AN401: 392 | AO401: 470 | AP401: 46561 | AQ401: 37721 | AR401: 27434 | AS401: 23101 | AT401: 18328 | AU401: 15214 | AV401: 13942 | AW401: 10660 | AX401: 9823 | AY401: 6259 | AZ401: 6320 | BA401: 3072 | BB401: 3939 | BC401: 1586 | BD401: 2308 | BE401: 778 | BF401: 950
A402: KANO | B402: RIMIN GADO | C402: =VLOOKUP(B402,'Cross river Land'!A:B,2,0) -> NG020033 | D402: =COUNTIF(C:C,C402) -> 1 | E402: 74289 | F402: 79279 | G402: 153568 | H402: 14275 | I402: 12133 | J402: 8838 | K402: 7649 | L402: 6453 | M402: 5227 | N402: 4686 | O402: 3371 | P402: 3258 | Q402: 1876 | R402: 2020 | S402: 1185 | T402: 1271 | U402: 581 | V402: 830 | W402: 248 | X402: 388 | Y402: 15190 | Z402: 13434 | AA402: 11236 | AB402: 8424 | AC402: 5658 | AD402: 4960 | AE402: 4476 | AF402: 3635 | AG402: 3439 | AH402: 2180 | AI402: 2323 | AJ402: 1024 | AK402: 1330 | AL402: 573 | AM402: 764 | AN402: 298 | AO402: 335 | AP402: 29465 | AQ402: 25567 | AR402: 20074 | AS402: 16073 | AT402: 12111 | AU402: 10187 | AV402: 9162 | AW402: 7006 | AX402: 6697 | AY402: 4056 | AZ402: 4343 | BA402: 2209 | BB402: 2601 | BC402: 1154 | BD402: 1594 | BE402: 546 | BF402: 723
A403: KANO | B403: ROGO | C403: =VLOOKUP(B403,'Cross river Land'!A:B,2,0) -> NG020034 | D403: =COUNTIF(C:C,C403) -> 1 | E403: 160428 | F403: 159830 | G403: 320258 | H403: 32474 | I403: 27590 | J403: 17457 | K403: 16671 | L403: 15323 | M403: 11735 | N403: 10243 | O403: 6529 | P403: 6457 | Q403: 3219 | R403: 4100 | S403: 1910 | T403: 2596 | U403: 1121 | V403: 1730 | W403: 552 | X403: 721 | Y403: 33890 | Z403: 27267 | AA403: 19692 | AB403: 15207 | AC403: 10138 | AD403: 9824 | AE403: 10289 | AF403: 7858 | AG403: 7353 | AH403: 4017 | AI403: 4764 | AJ403: 2434 | AK403: 2855 | AL403: 1193 | AM403: 1732 | AN403: 586 | AO403: 731 | AP403: 66364 | AQ403: 54857 | AR403: 37149 | AS403: 31878 | AT403: 25461 | AU403: 21559 | AV403: 20532 | AW403: 14387 | AX403: 13810 | AY403: 7236 | AZ403: 8864 | BA403: 4344 | BB403: 5451 | BC403: 2314 | BD403: 3462 | BE403: 1138 | BF403: 1452
A404: KANO | B404: SHANONO | C404: =VLOOKUP(B404,'Cross river Land'!A:B,2,0) -> NG020035 | D404: =COUNTIF(C:C,C404) -> 1 | E404: 100801 | F404: 97951 | G404: 198752 | H404: 20187 | I404: 15716 | J404: 12151 | K404: 10819 | L404: 8665 | M404: 7434 | N404: 6295 | O404: 4470 | P404: 4211 | Q404: 2507 | R404: 2697 | S404: 1355 | T404: 1610 | U404: 794 | V404: 1023 | W404: 444 | X404: 423 | Y404: 21456 | Z404: 16246 | AA404: 11659 | AB404: 9341 | AC404: 6396 | AD404: 5958 | AE404: 6027 | AF404: 4884 | AG404: 4406 | AH404: 2920 | AI404: 2852 | AJ404: 1531 | AK404: 1628 | AL404: 748 | AM404: 1059 | AN404: 377 | AO404: 463 | AP404: 41643 | AQ404: 31962 | AR404: 23810 | AS404: 20160 | AT404: 15061 | AU404: 13392 | AV404: 12322 | AW404: 9354 | AX404: 8617 | AY404: 5427 | AZ404: 5549 | BA404: 2886 | BB404: 3238 | BC404: 1542 | BD404: 2082 | BE404: 821 | BF404: 886
A405: KANO | B405: SUMAILA | C405: =VLOOKUP(B405,'Cross river Land'!A:B,2,0) -> NG020036 | D405: =COUNTIF(C:C,C405) -> 1 | E405: 165935 | F405: 166715 | G405: 332650 | H405: 31814 | I405: 27049 | J405: 18389 | K405: 17042 | L405: 15094 | M405: 12151 | N405: 11294 | O405: 7590 | P405: 7539 | Q405: 4238 | R405: 4637 | S405: 2100 | T405: 2692 | U405: 1139 | V405: 1651 | W405: 709 | X405: 807 | Y405: 33630 | Z405: 27255 | AA405: 19696 | AB405: 16312 | AC405: 11563 | AD405: 10286 | AE405: 10779 | AF405: 8277 | AG405: 8184 | AH405: 4829 | AI405: 5460 | AJ405: 2420 | AK405: 3097 | AL405: 1282 | AM405: 2048 | AN405: 751 | AO405: 846 | AP405: 65444 | AQ405: 54304 | AR405: 38085 | AS405: 33354 | AT405: 26657 | AU405: 22437 | AV405: 22073 | AW405: 15867 | AX405: 15723 | AY405: 9067 | AZ405: 10097 | BA405: 4520 | BB405: 5789 | BC405: 2421 | BD405: 3699 | BE405: 1460 | BF405: 1653
A406: KANO | B406: TAKAI | C406: =VLOOKUP(B406,'Cross river Land'!A:B,2,0) -> NG020037 | D406: =COUNTIF(C:C,C406) -> 1 | E406: 138689 | F406: 136560 | G406: 275249 | H406: 25481 | I406: 22371 | J406: 15638 | K406: 13814 | L406: 12949 | M406: 10510 | N406: 9535 | O406: 6160 | P406: 6437 | Q406: 3450 | R406: 3909 | S406: 1944 | T406: 2420 | U406: 1128 | V406: 1564 | W406: 614 | X406: 765 | Y406: 27025 | Z406: 22408 | AA406: 16075 | AB406: 13293 | AC406: 9122 | AD406: 8601 | AE406: 9075 | AF406: 6772 | AG406: 6879 | AH406: 3787 | AI406: 4454 | AJ406: 2189 | AK406: 2730 | AL406: 1186 | AM406: 1730 | AN406: 537 | AO406: 697 | AP406: 52506 | AQ406: 44779 | AR406: 31713 | AS406: 27107 | AT406: 22071 | AU406: 19111 | AV406: 18610 | AW406: 12932 | AX406: 13316 | AY406: 7237 | AZ406: 8363 | BA406: 4133 | BB406: 5150 | BC406: 2314 | BD406: 3294 | BE406: 1151 | BF406: 1462
A407: KANO | B407: TARAUNI | C407: =VLOOKUP(B407,'Cross river Land'!A:B,2,0) -> NG020038 | D407: =COUNTIF(C:C,C407) -> 1 | E407: 171137 | F407: 213031 | G407: 384168 | H407: 32430 | I407: 25630 | J407: 23625 | K407: 18543 | L407: 14804 | M407: 12647 | N407: 9884 | O407: 8416 | P407: 6875 | Q407: 4828 | R407: 3844 | S407: 2992 | T407: 2224 | U407: 1473 | V407: 1492 | W407: 718 | X407: 712 | Y407: 33618 | Z407: 27588 | AA407: 31167 | AB407: 27246 | AC407: 20804 | AD407: 16788 | AE407: 13090 | AF407: 11359 | AG407: 8641 | AH407: 6815 | AI407: 4658 | AJ407: 4691 | AK407: 2515 | AL407: 1910 | AM407: 1065 | AN407: 633 | AO407: 443 | AP407: 66048 | AQ407: 53218 | AR407: 54792 | AS407: 45789 | AT407: 35608 | AU407: 29435 | AV407: 22974 | AW407: 19775 | AX407: 15516 | AY407: 11643 | AZ407: 8502 | BA407: 7683 | BB407: 4739 | BC407: 3383 | BD407: 2557 | BE407: 1351 | BF407: 1155
A408: KANO | B408: TOFA | C408: =VLOOKUP(B408,'Cross river Land'!A:B,2,0) -> NG020039 | D408: =COUNTIF(C:C,C408) -> 1 | E408: 64480 | F408: 66288 | G408: 130768 | H408: 12702 | I408: 10390 | J408: 7707 | K408: 6298 | L408: 5477 | M408: 4491 | N408: 4059 | O408: 2830 | P408: 2853 | Q408: 1624 | R408: 1956 | S408: 924 | T408: 1124 | U408: 536 | V408: 779 | W408: 377 | X408: 353 | Y408: 13451 | Z408: 11023 | AA408: 8567 | AB408: 6744 | AC408: 4630 | AD408: 4093 | AE408: 3929 | AF408: 3230 | AG408: 2789 | AH408: 1860 | AI408: 1871 | AJ408: 1109 | AK408: 1138 | AL408: 596 | AM408: 674 | AN408: 299 | AO408: 285 | AP408: 26153 | AQ408: 21413 | AR408: 16274 | AS408: 13042 | AT408: 10107 | AU408: 8584 | AV408: 7988 | AW408: 6060 | AX408: 5642 | AY408: 3484 | AZ408: 3827 | BA408: 2033 | BB408: 2262 | BC408: 1132 | BD408: 1453 | BE408: 676 | BF408: 638
A409: KANO | B409: TSANYAWA | C409: =VLOOKUP(B409,'Cross river Land'!A:B,2,0) -> NG020040 | D409: =COUNTIF(C:C,C409) -> 1 | E409: 112753 | F409: 118478 | G409: 231231 | H409: 23082 | I409: 17502 | J409: 13494 | K409: 11372 | L409: 9368 | M409: 8211 | N409: 6885 | O409: 5423 | P409: 4640 | Q409: 3186 | R409: 3085 | S409: 1656 | T409: 1817 | U409: 821 | V409: 1150 | W409: 552 | X409: 509 | Y409: 24709 | Z409: 19300 | AA409: 15566 | AB409: 12550 | AC409: 8805 | AD409: 7423 | AE409: 6620 | AF409: 5735 | AG409: 4946 | AH409: 3558 | AI409: 3223 | AJ409: 1576 | AK409: 1701 | AL409: 701 | AM409: 1140 | AN409: 452 | AO409: 473 | AP409: 47791 | AQ409: 36802 | AR409: 29060 | AS409: 23922 | AT409: 18173 | AU409: 15634 | AV409: 13505 | AW409: 11158 | AX409: 9586 | AY409: 6744 | AZ409: 6308 | BA409: 3232 | BB409: 3518 | BC409: 1522 | BD409: 2290 | BE409: 1004 | BF409: 982
A410: KANO | B410: TUDUN WADA | C410: =VLOOKUP(B410,'Cross river Land'!A:B,2,0) -> NG020041 | D410: =COUNTIF(C:C,C410) -> 1 | E410: 161464 | F410: 160992 | G410: 322456 | H410: 31362 | I410: 27196 | J410: 17693 | K410: 17234 | L410: 14939 | M410: 11837 | N410: 10519 | O410: 6843 | P410: 7171 | Q410: 3735 | R410: 4249 | S410: 2104 | T410: 2473 | U410: 1085 | V410: 1625 | W410: 640 | X410: 759 | Y410: 33277 | Z410: 27652 | AA410: 18871 | AB410: 15035 | AC410: 10484 | AD410: 9934 | AE410: 10474 | AF410: 8118 | AG410: 7806 | AH410: 4431 | AI410: 4983 | AJ410: 2416 | AK410: 2966 | AL410: 1298 | AM410: 1864 | AN410: 631 | AO410: 752 | AP410: 64639 | AQ410: 54848 | AR410: 36564 | AS410: 32269 | AT410: 25423 | AU410: 21771 | AV410: 20993 | AW410: 14961 | AX410: 14977 | AY410: 8166 | AZ410: 9232 | BA410: 4520 | BB410: 5439 | BC410: 2383 | BD410: 3489 | BE410: 1271 | BF410: 1511
A411: KANO | B411: UNGOGO | C411: =VLOOKUP(B411,'Cross river Land'!A:B,2,0) -> NG020042 | D411: =COUNTIF(C:C,C411) -> 1 | E411: 325243 | F411: 366237 | G411: 691480 | H411: 67915 | I411: 52021 | J411: 39383 | K411: 32544 | L411: 29624 | M411: 24124 | N411: 19613 | O411: 14459 | P411: 13097 | Q411: 7546 | R411: 7429 | S411: 4679 | T411: 4499 | U411: 2530 | V411: 3096 | W411: 1298 | X411: 1386 | Y411: 70503 | Z411: 55667 | AA411: 48401 | AB411: 39502 | AC411: 29240 | AD411: 25396 | AE411: 21258 | AF411: 18240 | AG411: 15789 | AH411: 10935 | AI411: 9531 | AJ411: 7395 | AK411: 5627 | AL411: 3373 | AM411: 2881 | AN411: 1379 | AO411: 1120 | AP411: 138418 | AQ411: 107688 | AR411: 87784 | AS411: 72046 | AT411: 58864 | AU411: 49520 | AV411: 40871 | AW411: 32699 | AX411: 28886 | AY411: 18481 | AZ411: 16960 | BA411: 12074 | BB411: 10126 | BC411: 5903 | BD411: 5977 | BE411: 2677 | BF411: 2506
A412: KANO | B412: WARAWA | C412: =VLOOKUP(B412,'Cross river Land'!A:B,2,0) -> NG020043 | D412: =COUNTIF(C:C,C412) -> 1 | E412: 91262 | F412: 94252 | G412: 185514 | H412: 17176 | I412: 14881 | J412: 10213 | K412: 8585 | L412: 8180 | M412: 6783 | N412: 6458 | O412: 4108 | P412: 4488 | Q412: 2043 | R412: 2641 | S412: 1226 | T412: 1728 | U412: 804 | V412: 1145 | W412: 346 | X412: 457 | Y412: 17619 | Z412: 16363 | AA412: 11621 | AB412: 9499 | AC412: 5862 | AD412: 5836 | AE412: 5806 | AF412: 4470 | AG412: 4565 | AH412: 2675 | AI412: 3259 | AJ412: 1720 | AK412: 2036 | AL412: 878 | AM412: 1178 | AN412: 437 | AO412: 428 | AP412: 34795 | AQ412: 31244 | AR412: 21834 | AS412: 18084 | AT412: 14042 | AU412: 12619 | AV412: 12264 | AW412: 8578 | AX412: 9053 | AY412: 4718 | AZ412: 5900 | BA412: 2946 | BB412: 3764 | BC412: 1682 | BD412: 2323 | BE412: 783 | BF412: 885
... A533: NASARAWA | B533: LAFIA | C533: =VLOOKUP(B533,'Cross river Land'!A:B,2,0) -> NG026008 | D533: =COUNTIF(C:C,C533) -> 1 | E533: 195120 | F533: 199169 | G533: 394289 | H533: 35887 | I533: 29629 | J533: 24391 | K533: 21780 | L533: 18238 | M533: 15374 | N533: 12043 | O533: 9491 | P533: 7771 | Q533: 5411 | R533: 4366 | S533: 2981 | T533: 2592 | U533: 2120 | V533: 1571 | W533: 837 | X533: 638 | Y533: 36926 | Z533: 29963 | AA533: 24727 | AB533: 21543 | AC533: 16667 | AD533: 14731 | AE533: 12965 | AF533: 10804 | AG533: 8655 | AH533: 6561 | AI533: 4993 | AJ533: 3425 | AK533: 2472 | AL533: 1977 | AM533: 1343 | AN533: 827 | AO533: 590 | AP533: 72813 | AQ533: 59592 | AR533: 49118 | AS533: 43323 | AT533: 34905 | AU533: 30105 | AV533: 25008 | AW533: 20295 | AX533: 16426 | AY533: 11972 | AZ533: 9359 | BA533: 6406 | BB533: 5064 | BC533: 4097 | BD533: 2914 | BE533: 1664 | BF533: 1228
A534: NASARAWA | B534: Nasarawa | C534: NG026009 | D534: =COUNTIF(C:C,C534) -> 1 | E534: 117093 | F534: 121884 | G534: 238977 | H534: 22016 | I534: 17158 | J534: 14341 | K534: 12637 | L534: 10502 | M534: 8822 | N534: 7390 | O534: 5741 | P534: 4833 | Q534: 3442 | R534: 2795 | S534: 2175 | T534: 1852 | U534: 1289 | V534: 924 | W534: 735 | X534: 441 | Y534: 22600 | Z534: 17874 | AA534: 15075 | AB534: 13138 | AC534: 10795 | AD534: 8973 | AE534: 7577 | AF534: 6254 | AG534: 5279 | AH534: 4012 | AI534: 3123 | AJ534: 2226 | AK534: 1559 | AL534: 1408 | AM534: 964 | AN534: 608 | AO534: 419 | AP534: 44616 | AQ534: 35032 | AR534: 29416 | AS534: 25775 | AT534: 21297 | AU534: 17795 | AV534: 14967 | AW534: 11995 | AX534: 10112 | AY534: 7454 | AZ534: 5918 | BA534: 4401 | BB534: 3411 | BC534: 2697 | BD534: 1888 | BE534: 1343 | BF534: 860
A535: NASARAWA | B535: Nasarawa-Eggon | C535: =VLOOKUP(B535,'Cross river Land'!A:B,2,0) -> NG026010 | D535: =COUNTIF(C:C,C535) -> 1 | E535: 130214 | F535: 132018 | G535: 262232 | H535: 24834 | I535: 19194 | J535: 15819 | K535: 13808 | L535: 11369 | M535: 9782 | N535: 7977 | O535: 6337 | P535: 5296 | Q535: 3845 | R535: 3236 | S535: 2445 | T535: 1872 | U535: 1699 | V535: 1256 | W535: 984 | X535: 461 | Y535: 25354 | Z535: 19766 | AA535: 16537 | AB535: 14400 | AC535: 10789 | AD535: 9335 | AE535: 8103 | AF535: 7011 | AG535: 5547 | AH535: 4312 | AI535: 3200 | AJ535: 2494 | AK535: 1781 | AL535: 1298 | AM535: 991 | AN535: 613 | AO535: 487 | AP535: 50188 | AQ535: 38960 | AR535: 32356 | AS535: 28208 | AT535: 22158 | AU535: 19117 | AV535: 16080 | AW535: 13348 | AX535: 10843 | AY535: 8157 | AZ535: 6436 | BA535: 4939 | BB535: 3653 | BC535: 2997 | BD535: 2247 | BE535: 1597 | BF535: 948
A536: NASARAWA | B536: Obi | C536: NG026011 | D536: =COUNTIF(C:C,C536) -> 1 | E536: 95217 | F536: 96172 | G536: 191389 | H536: 18418 | I536: 14146 | J536: 11814 | K536: 10640 | L536: 8401 | M536: 6932 | N536: 5575 | O536: 4505 | P536: 3678 | Q536: 2763 | R536: 2274 | S536: 1765 | T536: 1558 | U536: 1247 | V536: 736 | W536: 390 | X536: 375 | Y536: 18868 | Z536: 14586 | AA536: 12948 | AB536: 11242 | AC536: 7584 | AD536: 6362 | AE536: 5614 | AF536: 4685 | AG536: 3865 | AH536: 2958 | AI536: 2371 | AJ536: 1493 | AK536: 1224 | AL536: 852 | AM536: 711 | AN536: 459 | AO536: 350 | AP536: 37286 | AQ536: 28732 | AR536: 24762 | AS536: 21882 | AT536: 15985 | AU536: 13294 | AV536: 11189 | AW536: 9190 | AX536: 7543 | AY536: 5721 | AZ536: 4645 | BA536: 3258 | BB536: 2782 | BC536: 2099 | BD536: 1447 | BE536: 849 | BF536: 725
A537: NASARAWA | B537: TOTO | C537: =VLOOKUP(B537,'Cross river Land'!A:B,2,0) -> NG026012 | D537: =COUNTIF(C:C,C537) -> 1 | E537: 68344 | F537: 69571 | G537: 137915 | H537: 13403 | I537: 10077 | J537: 8232 | K537: 7244 | L537: 5822 | M537: 5069 | N537: 4123 | O537: 3371 | P537: 2771 | Q537: 2062 | R537: 1661 | S537: 1322 | T537: 945 | U537: 923 | V537: 518 | W537: 514 | X537: 287 | Y537: 13923 | Z537: 10585 | AA537: 8665 | AB537: 7416 | AC537: 5590 | AD537: 4714 | AE537: 4110 | AF537: 3632 | AG537: 2883 | AH537: 2246 | AI537: 1677 | AJ537: 1311 | AK537: 906 | AL537: 797 | AM537: 533 | AN537: 351 | AO537: 232 | AP537: 27326 | AQ537: 20662 | AR537: 16897 | AS537: 14660 | AT537: 11412 | AU537: 9783 | AV537: 8233 | AW537: 7003 | AX537: 5654 | AY537: 4308 | AZ537: 3338 | BA537: 2633 | BB537: 1851 | BC537: 1720 | BD537: 1051 | BE537: 865 | BF537: 519
A538: NASARAWA | B538: WAMBA | C538: =VLOOKUP(B538,'Cross river Land'!A:B,2,0) -> NG026013 | D538: =COUNTIF(C:C,C538) -> 1 | E538: 53431 | F538: 54849 | G538: 108280 | H538: 10354 | I538: 7810 | J538: 6409 | K538: 5589 | L538: 4398 | M538: 3974 | N538: 3208 | O538: 2624 | P538: 2170 | Q538: 1653 | R538: 1253 | S538: 1262 | T538: 840 | U538: 870 | V538: 433 | W538: 370 | X538: 214 | Y538: 10692 | Z538: 8197 | AA538: 6676 | AB538: 5745 | AC538: 4528 | AD538: 3882 | AE538: 3417 | AF538: 2954 | AG538: 2314 | AH538: 1834 | AI538: 1317 | AJ538: 1041 | AK538: 680 | AL538: 688 | AM538: 397 | AN538: 257 | AO538: 230 | AP538: 21046 | AQ538: 16007 | AR538: 13085 | AS538: 11334 | AT538: 8926 | AU538: 7856 | AV538: 6625 | AW538: 5578 | AX538: 4484 | AY538: 3487 | AZ538: 2570 | BA538: 2303 | BB538: 1520 | BC538: 1558 | BD538: 830 | BE538: 627 | BF538: 444
A539: NIGER | B539: AGAIE | C539: =VLOOKUP(B539,'Cross river Land'!A:B,2,0) -> NG027001 | D539: =COUNTIF(C:C,C539) -> 1 | E539: 93984 | F539: 96222 | G539: 190206 | H539: 18783 | I539: 14080 | J539: 11378 | K539: 9906 | L539: 7984 | M539: 6882 | N539: 5761 | O539: 4581 | P539: 3795 | Q539: 2713 | R539: 2310 | S539: 1728 | T539: 1485 | U539: 1208 | V539: 668 | W539: 468 | X539: 254 | Y539: 19839 | Z539: 14859 | AA539: 12062 | AB539: 9775 | AC539: 7332 | AD539: 6497 | AE539: 5811 | AF539: 5068 | AG539: 4058 | AH539: 3112 | AI539: 2530 | AJ539: 1454 | AK539: 1501 | AL539: 909 | AM539: 756 | AN539: 379 | AO539: 280 | AP539: 38622 | AQ539: 28939 | AR539: 23440 | AS539: 19681 | AT539: 15316 | AU539: 13379 | AV539: 11572 | AW539: 9649 | AX539: 7853 | AY539: 5825 | AZ539: 4840 | BA539: 3182 | BB539: 2986 | BC539: 2117 | BD539: 1424 | BE539: 847 | BF539: 534
A540: NIGER | B540: AGWARA | C540: =VLOOKUP(B540,'Cross river Land'!A:B,2,0) -> NG027002 | D540: =COUNTIF(C:C,C540) -> 1 | E540: 35897 | F540: 37760 | G540: 73657 | H540: 7664 | I540: 5752 | J540: 4067 | K540: 3503 | L540: 3142 | M540: 2586 | N540: 2086 | O540: 1793 | P540: 1329 | Q540: 994 | R540: 756 | S540: 723 | T540: 456 | U540: 390 | V540: 322 | W540: 181 | X540: 153 | Y540: 8013 | Z540: 5965 | AA540: 4230 | AB540: 3788 | AC540: 2803 | AD540: 2660 | AE540: 2343 | AF540: 2010 | AG540: 1599 | AH540: 1227 | AI540: 932 | AJ540: 641 | AK540: 495 | AL540: 416 | AM540: 333 | AN540: 186 | AO540: 119 | AP540: 15677 | AQ540: 11717 | AR540: 8297 | AS540: 7291 | AT540: 5945 | AU540: 5246 | AV540: 4429 | AW540: 3803 | AX540: 2928 | AY540: 2221 | AZ540: 1688 | BA540: 1364 | BB540: 951 | BC540: 806 | BD540: 655 | BE540: 367 | BF540: 272
A541: NIGER | B541: BIDA | C541: =VLOOKUP(B541,'Cross river Land'!A:B,2,0) -> NG027003 | D541: =COUNTIF(C:C,C541) -> 1 | E541: 140672 | F541: 145818 | G541: 286490 | H541: 26164 | I541: 20590 | J541: 17595 | K541: 16182 | L541: 13664 | M541: 11427 | N541: 8556 | O541: 7029 | P541: 5349 | Q541: 3985 | R541: 3005 | S541: 2398 | T541: 1708 | U541: 1335 | V541: 794 | W541: 518 | X541: 373 | Y541: 28434 | Z541: 22332 | AA541: 17856 | AB541: 15479 | AC541: 12295 | AD541: 10694 | AE541: 9051 | AF541: 7729 | AG541: 6268 | AH541: 4749 | AI541: 3326 | AJ541: 2529 | AK541: 1883 | AL541: 1419 | AM541: 902 | AN541: 568 | AO541: 304 | AP541: 54598 | AQ541: 42922 | AR541: 35451 | AS541: 31661 | AT541: 25959 | AU541: 22121 | AV541: 17607 | AW541: 14758 | AX541: 11617 | AY541: 8734 | AZ541: 6331 | BA541: 4927 | BB541: 3591 | BC541: 2754 | BD541: 1696 | BE541: 1086 | BF541: 677
A542: NIGER | B542: BORGU | C542: =VLOOKUP(B542,'Cross river Land'!A:B,2,0) -> NG027004 | D542: =COUNTIF(C:C,C542) -> 1 | E542: 116153 | F542: 119777 | G542: 235930 | H542: 22714 | I542: 18202 | J542: 14070 | K542: 12169 | L542: 10382 | M542: 8739 | N542: 7162 | O542: 5549 | P542: 4659 | Q542: 3294 | R542: 2839 | S542: 1875 | T542: 1595 | U542: 1184 | V542: 852 | W542: 498 | X542: 370 | Y542: 23364 | Z542: 18282 | AA542: 14224 | AB542: 11726 | AC542: 8819 | AD542: 8513 | AE542: 7762 | AF542: 6857 | AG542: 5395 | AH542: 4099 | AI542: 3252 | AJ542: 2433 | AK542: 1947 | AL542: 1248 | AM542: 978 | AN542: 502 | AO542: 376 | AP542: 46078 | AQ542: 36484 | AR542: 28294 | AS542: 23895 | AT542: 19201 | AU542: 17252 | AV542: 14924 | AW542: 12406 | AX542: 10054 | AY542: 7393 | AZ542: 6091 | BA542: 4308 | BB542: 3542 | BC542: 2432 | BD542: 1830 | BE542: 1000 | BF542: 746
